<mujoco model="g1_29dof_rev_1_0">
  <compiler angle="radian" meshdir="meshes"/>

  <option iterations="100" solver="Newton" cone="elliptic" gravity="0 0 -9.81"/>
  <default>
    <joint damping="0.001" armature="0.01" frictionloss="0.1"/>
  </default>

  <asset>
    <mesh name="pelvis" file="pelvis.STL"/>
    <mesh name="pelvis_contour_link" file="pelvis_contour_link.STL"/>
    <mesh name="left_hip_pitch_link" file="left_hip_pitch_link.STL"/>
    <mesh name="left_hip_roll_link" file="left_hip_roll_link.STL"/>
    <mesh name="left_hip_yaw_link" file="left_hip_yaw_link.STL"/>
    <mesh name="left_knee_link" file="left_knee_link.STL"/>
    <mesh name="left_ankle_pitch_link" file="left_ankle_pitch_link.STL"/>
    <mesh name="left_ankle_roll_link" file="left_ankle_roll_link.STL"/>
    <mesh name="right_hip_pitch_link" file="right_hip_pitch_link.STL"/>
    <mesh name="right_hip_roll_link" file="right_hip_roll_link.STL"/>
    <mesh name="right_hip_yaw_link" file="right_hip_yaw_link.STL"/>
    <mesh name="right_knee_link" file="right_knee_link.STL"/>
    <mesh name="right_ankle_pitch_link" file="right_ankle_pitch_link.STL"/>
    <mesh name="right_ankle_roll_link" file="right_ankle_roll_link.STL"/>
    <mesh name="waist_yaw_link" file="waist_yaw_link_rev_1_0.STL"/>
    <mesh name="waist_roll_link" file="waist_roll_link_rev_1_0.STL"/>
    <mesh name="torso_link" file="torso_link_rev_1_0.STL"/>
    <mesh name="logo_link" file="logo_link.STL"/>
    <mesh name="head_link" file="head_link.STL"/>
    <mesh name="left_shoulder_pitch_link" file="left_shoulder_pitch_link.STL"/>
    <mesh name="left_shoulder_roll_link" file="left_shoulder_roll_link.STL"/>
    <mesh name="left_shoulder_yaw_link" file="left_shoulder_yaw_link.STL"/>
    <mesh name="left_elbow_link" file="left_elbow_link.STL"/>
    <mesh name="left_wrist_roll_link" file="left_wrist_roll_link.STL"/>
    <mesh name="left_wrist_pitch_link" file="left_wrist_pitch_link.STL"/>
    <mesh name="left_wrist_yaw_link" file="left_wrist_yaw_link.STL"/>
    <mesh name="left_rubber_hand" file="left_rubber_hand.STL"/>
    <mesh name="right_shoulder_pitch_link" file="right_shoulder_pitch_link.STL"/>
    <mesh name="right_shoulder_roll_link" file="right_shoulder_roll_link.STL"/>
    <mesh name="right_shoulder_yaw_link" file="right_shoulder_yaw_link.STL"/>
    <mesh name="right_elbow_link" file="right_elbow_link.STL"/>
    <mesh name="right_wrist_roll_link" file="right_wrist_roll_link.STL"/>
    <mesh name="right_wrist_pitch_link" file="right_wrist_pitch_link.STL"/>
    <mesh name="right_wrist_yaw_link" file="right_wrist_yaw_link.STL"/>
    <mesh name="right_rubber_hand" file="right_rubber_hand.STL"/>
  </asset>

  <worldbody>
    <body name="pelvis" pos="0 0 0.793">
      <inertial pos="0 0 -0.07605" quat="1 0 -0.000399148 0" mass="3.813" diaginertia="0.010549 0.0093089 0.0079184"/>
      <joint name="floating_base_joint" type="free" limited="false" actuatorfrclimited="false"/>
      <geom type="mesh" contype="0" conaffinity="0" group="1" density="0" rgba="0.2 0.2 0.2 1" mesh="pelvis"/>
      <geom type="mesh" contype="0" conaffinity="0" group="1" density="0" rgba="0.7 0.7 0.7 1" mesh="pelvis_contour_link"/>
      <geom type="mesh" rgba="0.7 0.7 0.7 1" mesh="pelvis_contour_link"/>
      <site name="imu_in_pelvis" size="0.01" pos="0.04525 0 -0.08339"/>
      <body name="left_hip_pitch_link" pos="0 0.064452 -0.1027">
        <inertial pos="0.002741 0.047791 -0.02606" quat="0.954862 0.293964 0.0302556 0.030122" mass="1.35" diaginertia="0.00181517 0.00153422 0.00116212"/>
        <joint name="left_hip_pitch_joint" pos="0 0 0" axis="0 1 0" range="-2.5307 2.8798" actuatorfrcrange="-88 88"/>
        <geom type="mesh" contype="0" conaffinity="0" group="1" density="0" rgba="0.2 0.2 0.2 1" mesh="left_hip_pitch_link"/>
        <geom type="mesh" rgba="0.2 0.2 0.2 1" mesh="left_hip_pitch_link"/>
        <body name="left_hip_roll_link" pos="0 0.052 -0.030465" quat="0.996179 0 -0.0873386 0">
          <inertial pos="0.029812 -0.001045 -0.087934" quat="0.977808 -1.97119e-05 0.205576 -0.0403793" mass="1.52" diaginertia="0.00254986 0.00241169 0.00148755"/>
          <joint name="left_hip_roll_joint" pos="0 0 0" axis="1 0 0" range="-0.5236 2.9671" actuatorfrcrange="-139 139"/>
          <geom type="mesh" contype="0" conaffinity="0" group="1" density="0" rgba="0.7 0.7 0.7 1" mesh="left_hip_roll_link"/>
          <geom type="mesh" rgba="0.7 0.7 0.7 1" mesh="left_hip_roll_link"/>
          <body name="left_hip_yaw_link" pos="0.025001 0 -0.12412">
            <inertial pos="-0.057709 -0.010981 -0.15078" quat="0.600598 0.15832 0.223482 0.751181" mass="1.702" diaginertia="0.00776166 0.00717575 0.00160139"/>
            <joint name="left_hip_yaw_joint" pos="0 0 0" axis="0 0 1" range="-2.7576 2.7576" actuatorfrcrange="-88 88"/>
            <geom type="mesh" contype="0" conaffinity="0" group="1" density="0" rgba="0.7 0.7 0.7 1" mesh="left_hip_yaw_link"/>
            <geom type="mesh" rgba="0.7 0.7 0.7 1" mesh="left_hip_yaw_link"/>
            <body name="left_knee_link" pos="-0.078273 0.0021489 -0.17734" quat="0.996179 0 0.0873386 0">
              <inertial pos="0.005457 0.003964 -0.12074" quat="0.923418 -0.0327699 0.0158246 0.382067" mass="1.932" diaginertia="0.0113804 0.0112778 0.00146458"/>
              <joint name="left_knee_joint" pos="0 0 0" axis="0 1 0" range="-0.087267 2.8798" actuatorfrcrange="-139 139"/>
              <geom type="mesh" contype="0" conaffinity="0" group="1" density="0" rgba="0.7 0.7 0.7 1" mesh="left_knee_link"/>
              <geom type="mesh" rgba="0.7 0.7 0.7 1" mesh="left_knee_link"/>
              <body name="left_ankle_pitch_link" pos="0 -9.4445e-05 -0.30001">
                <inertial pos="-0.007269 0 0.011137" quat="0.603053 0.369225 0.369225 0.603053" mass="0.074" diaginertia="1.89e-05 1.40805e-05 6.9195e-06"/>
                <joint name="left_ankle_pitch_joint" pos="0 0 0" axis="0 1 0" range="-0.87267 0.5236" actuatorfrcrange="-50 50"/>
                <geom type="mesh" contype="0" conaffinity="0" group="1" density="0" rgba="0.7 0.7 0.7 1" mesh="left_ankle_pitch_link"/>
                <geom type="mesh" rgba="0.7 0.7 0.7 1" mesh="left_ankle_pitch_link"/>
                <body name="left_ankle_roll_link" pos="0 0 -0.017558">
                  <inertial pos="0.026505 0 -0.016425" quat="-0.000481092 0.728482 -0.000618967 0.685065" mass="0.608" diaginertia="0.00167218 0.0016161 0.000217621"/>
                  <joint name="left_ankle_roll_joint" pos="0 0 0" axis="1 0 0" range="-0.2618 0.2618" actuatorfrcrange="-50 50"/>
                  <geom type="mesh" contype="0" conaffinity="0" group="1" density="0" rgba="0.2 0.2 0.2 1" mesh="left_ankle_roll_link"/>
                  <geom size="0.005" pos="-0.05 0.025 -0.03" rgba="0.2 0.2 0.2 1" friction="1.5 0.02 0.002" condim="4"/>
                  <geom size="0.005" pos="-0.05 -0.025 -0.03" rgba="0.2 0.2 0.2 1" friction="1.5 0.02 0.002" condim="4"/>
                  <geom size="0.005" pos="0.12 0.03 -0.03" rgba="0.2 0.2 0.2 1" friction="1.5 0.02 0.002" condim="4"/>
                  <geom size="0.005" pos="0.12 -0.03 -0.03" rgba="0.2 0.2 0.2 1" friction="1.5 0.02 0.002" condim="4"/>
                </body>
              </body>
            </body>
          </body>
        </body>
      </body>
      <body name="right_hip_pitch_link" pos="0 -0.064452 -0.1027">
        <inertial pos="0.002741 -0.047791 -0.02606" quat="0.954862 -0.293964 0.0302556 -0.030122" mass="1.35" diaginertia="0.00181517 0.00153422 0.00116212"/>
        <joint name="right_hip_pitch_joint" pos="0 0 0" axis="0 1 0" range="-2.5307 2.8798" actuatorfrcrange="-88 88"/>
        <geom type="mesh" contype="0" conaffinity="0" group="1" density="0" rgba="0.2 0.2 0.2 1" mesh="right_hip_pitch_link"/>
        <geom type="mesh" rgba="0.2 0.2 0.2 1" mesh="right_hip_pitch_link"/>
        <body name="right_hip_roll_link" pos="0 -0.052 -0.030465" quat="0.996179 0 -0.0873386 0">
          <inertial pos="0.029812 0.001045 -0.087934" quat="0.977808 1.97119e-05 0.205576 0.0403793" mass="1.52" diaginertia="0.00254986 0.00241169 0.00148755"/>
          <joint name="right_hip_roll_joint" pos="0 0 0" axis="1 0 0" range="-2.9671 0.5236" actuatorfrcrange="-139 139"/>
          <geom type="mesh" contype="0" conaffinity="0" group="1" density="0" rgba="0.7 0.7 0.7 1" mesh="right_hip_roll_link"/>
          <geom type="mesh" rgba="0.7 0.7 0.7 1" mesh="right_hip_roll_link"/>
          <body name="right_hip_yaw_link" pos="0.025001 0 -0.12412">
            <inertial pos="-0.057709 0.010981 -0.15078" quat="0.751181 0.223482 0.15832 0.600598" mass="1.702" diaginertia="0.00776166 0.00717575 0.00160139"/>
            <joint name="right_hip_yaw_joint" pos="0 0 0" axis="0 0 1" range="-2.7576 2.7576" actuatorfrcrange="-88 88"/>
            <geom type="mesh" contype="0" conaffinity="0" group="1" density="0" rgba="0.7 0.7 0.7 1" mesh="right_hip_yaw_link"/>
            <geom type="mesh" rgba="0.7 0.7 0.7 1" mesh="right_hip_yaw_link"/>
            <body name="right_knee_link" pos="-0.078273 -0.0021489 -0.17734" quat="0.996179 0 0.0873386 0">
              <inertial pos="0.005457 -0.003964 -0.12074" quat="0.923439 0.0345276 0.0116333 -0.382012" mass="1.932" diaginertia="0.011374 0.0112843 0.00146452"/>
              <joint name="right_knee_joint" pos="0 0 0" axis="0 1 0" range="-0.087267 2.8798" actuatorfrcrange="-139 139"/>
              <geom type="mesh" contype="0" conaffinity="0" group="1" density="0" rgba="0.7 0.7 0.7 1" mesh="right_knee_link"/>
              <geom type="mesh" rgba="0.7 0.7 0.7 1" mesh="right_knee_link"/>
              <body name="right_ankle_pitch_link" pos="0 9.4445e-05 -0.30001">
                <inertial pos="-0.007269 0 0.011137" quat="0.603053 0.369225 0.369225 0.603053" mass="0.074" diaginertia="1.89e-05 1.40805e-05 6.9195e-06"/>
                <joint name="right_ankle_pitch_joint" pos="0 0 0" axis="0 1 0" range="-0.87267 0.5236" actuatorfrcrange="-50 50"/>
                <geom type="mesh" contype="0" conaffinity="0" group="1" density="0" rgba="0.7 0.7 0.7 1" mesh="right_ankle_pitch_link"/>
                <geom type="mesh" rgba="0.7 0.7 0.7 1" mesh="right_ankle_pitch_link"/>
                <body name="right_ankle_roll_link" pos="0 0 -0.017558">
                  <inertial pos="0.026505 0 -0.016425" quat="0.000481092 0.728482 0.000618967 0.685065" mass="0.608" diaginertia="0.00167218 0.0016161 0.000217621"/>
                  <joint name="right_ankle_roll_joint" pos="0 0 0" axis="1 0 0" range="-0.2618 0.2618" actuatorfrcrange="-50 50"/>
                  <geom type="mesh" contype="0" conaffinity="0" group="1" density="0" rgba="0.2 0.2 0.2 1" mesh="right_ankle_roll_link"/>
                  <geom size="0.005" pos="-0.05 0.025 -0.03" rgba="0.2 0.2 0.2 1" friction="1.5 0.02 0.002" condim="4"/>
                  <geom size="0.005" pos="-0.05 -0.025 -0.03" rgba="0.2 0.2 0.2 1" friction="1.5 0.02 0.002" condim="4"/>
                  <geom size="0.005" pos="0.12 0.03 -0.03" rgba="0.2 0.2 0.2 1" friction="1.5 0.02 0.002" condim="4"/>
                  <geom size="0.005" pos="0.12 -0.03 -0.03" rgba="0.2 0.2 0.2 1" friction="1.5 0.02 0.002" condim="4"/>
                </body>
              </body>
            </body>
          </body>
        </body>
      </body>
      <body name="waist_yaw_link">
        <inertial pos="0.003494 0.000233 0.018034" quat="0.289697 0.591001 -0.337795 0.672821" mass="0.214" diaginertia="0.000163531 0.000107714 0.000102205"/>
        <joint name="waist_yaw_joint" pos="0 0 0" axis="0 0 1" range="-2.618 2.618" actuatorfrcrange="-88 88"/>
        <geom type="mesh" contype="0" conaffinity="0" group="1" density="0" rgba="0.7 0.7 0.7 1" mesh="waist_yaw_link"/>
        <body name="waist_roll_link" pos="-0.0039635 0 0.044">
          <inertial pos="0 2.3e-05 0" quat="0.5 0.5 -0.5 0.5" mass="0.086" diaginertia="8.245e-06 7.079e-06 6.339e-06"/>
          <joint name="waist_roll_joint" pos="0 0 0" axis="1 0 0" range="-0.52 0.52" actuatorfrcrange="-50 50"/>
          <geom type="mesh" contype="0" conaffinity="0" group="1" density="0" rgba="0.7 0.7 0.7 1" mesh="waist_roll_link"/>
          <body name="torso_link">
            <inertial pos="0.00203158 0.000339683 0.184568" quat="0.999803 -6.03319e-05 0.0198256 0.00131986" mass="7.818" diaginertia="0.121847 0.109825 0.0273735"/>
            <joint name="waist_pitch_joint" pos="0 0 0" axis="0 1 0" range="-0.52 0.52" actuatorfrcrange="-50 50"/>
            <geom type="mesh" contype="0" conaffinity="0" group="1" density="0" rgba="0.7 0.7 0.7 1" mesh="torso_link"/>
            <geom type="mesh" rgba="0.7 0.7 0.7 1" mesh="torso_link"/>
            <geom pos="0.0039635 0 -0.044" quat="1 0 0 0" type="mesh" contype="0" conaffinity="0" group="1" density="0" rgba="0.2 0.2 0.2 1" mesh="logo_link"/>
            <geom pos="0.0039635 0 -0.044" quat="1 0 0 0" type="mesh" rgba="0.2 0.2 0.2 1" mesh="logo_link"/>
            <geom pos="0.0039635 0 -0.044" type="mesh" contype="0" conaffinity="0" group="1" density="0" rgba="0.2 0.2 0.2 1" mesh="head_link"/>
            <geom pos="0.0039635 0 -0.044" type="mesh" rgba="0.2 0.2 0.2 1" mesh="head_link"/>
            <camera name="robot_pov" pos="0.10 0 0.12" xyaxes="0 -1 0 0.259 0 0.966" fovy="75"/>
            <site name="imu_in_torso" size="0.01" pos="-0.03959 -0.00224 0.14792"/>
            <body name="left_shoulder_pitch_link" pos="0.0039563 0.10022 0.24778" quat="0.990264 0.139201 1.38722e-05 -9.86868e-05">
              <inertial pos="0 0.035892 -0.011628" quat="0.654152 0.0130458 -0.326267 0.68225" mass="0.718" diaginertia="0.000465864 0.000432842 0.000406394"/>
              <joint name="left_shoulder_pitch_joint" pos="0 0 0" axis="0 1 0" range="-3.0892 2.6704" actuatorfrcrange="-25 25"/>
              <geom type="mesh" contype="0" conaffinity="0" group="1" density="0" rgba="0.7 0.7 0.7 1" mesh="left_shoulder_pitch_link"/>
              <geom size="0.03 0.025" pos="0 0.04 -0.01" quat="0.707107 0 0.707107 0" type="cylinder" rgba="0.7 0.7 0.7 1"/>
              <body name="left_shoulder_roll_link" pos="0 0.038 -0.013831" quat="0.990268 -0.139172 0 0">
                <inertial pos="-0.000227 0.00727 -0.063243" quat="0.701256 -0.0196223 -0.00710317 0.712604" mass="0.643" diaginertia="0.000691311 0.000618011 0.000388977"/>
                <joint name="left_shoulder_roll_joint" pos="0 0 0" axis="1 0 0" range="-1.5882 2.2515" actuatorfrcrange="-25 25"/>
                <geom type="mesh" contype="0" conaffinity="0" group="1" density="0" rgba="0.7 0.7 0.7 1" mesh="left_shoulder_roll_link"/>
                <geom size="0.03 0.015" pos="-0.004 0.006 -0.053" type="cylinder" rgba="0.7 0.7 0.7 1"/>
                <body name="left_shoulder_yaw_link" pos="0 0.00624 -0.1032">
                  <inertial pos="0.010773 -0.002949 -0.072009" quat="0.716879 -0.0964829 -0.0679942 0.687134" mass="0.734" diaginertia="0.00106187 0.00103217 0.000400661"/>
                  <joint name="left_shoulder_yaw_joint" pos="0 0 0" axis="0 0 1" range="-2.618 2.618" actuatorfrcrange="-25 25"/>
                  <geom type="mesh" contype="0" conaffinity="0" group="1" density="0" rgba="0.7 0.7 0.7 1" mesh="left_shoulder_yaw_link"/>
                  <geom type="mesh" rgba="0.7 0.7 0.7 1" mesh="left_shoulder_yaw_link"/>
                  <body name="left_elbow_link" pos="0.015783 0 -0.080518">
                    <inertial pos="0.064956 0.004454 -0.010062" quat="0.541765 0.636132 0.388821 0.388129" mass="0.6" diaginertia="0.000443035 0.000421612 0.000259353"/>
                    <joint name="left_elbow_joint" pos="0 0 0" axis="0 1 0" range="-1.0472 2.0944" actuatorfrcrange="-25 25"/>
                    <geom type="mesh" contype="0" conaffinity="0" group="1" density="0" rgba="0.7 0.7 0.7 1" mesh="left_elbow_link"/>
                    <geom type="mesh" rgba="0.7 0.7 0.7 1" mesh="left_elbow_link"/>
                    <body name="left_wrist_roll_link" pos="0.1 0.00188791 -0.01">
                      <inertial pos="0.0171394 0.000537591 4.8864e-07" quat="0.575338 0.411667 -0.574906 0.411094" mass="0.085445" diaginertia="5.48211e-05 4.96646e-05 3.57798e-05"/>
                      <joint name="left_wrist_roll_joint" pos="0 0 0" axis="1 0 0" range="-1.97222 1.97222" actuatorfrcrange="-25 25"/>
                      <geom type="mesh" contype="0" conaffinity="0" group="1" density="0" rgba="0.7 0.7 0.7 1" mesh="left_wrist_roll_link"/>
                      <geom type="mesh" rgba="0.7 0.7 0.7 1" mesh="left_wrist_roll_link"/>
                      <body name="left_wrist_pitch_link" pos="0.038 0 0">
                        <inertial pos="0.0229999 -0.00111685 -0.00111658" quat="0.249998 0.661363 0.293036 0.643608" mass="0.48405" diaginertia="0.000430353 0.000429873 0.000164648"/>
                        <joint name="left_wrist_pitch_joint" pos="0 0 0" axis="0 1 0" range="-1.61443 1.61443" actuatorfrcrange="-5 5"/>
                        <geom type="mesh" contype="0" conaffinity="0" group="1" density="0" rgba="0.7 0.7 0.7 1" mesh="left_wrist_pitch_link"/>
                        <geom type="mesh" rgba="0.7 0.7 0.7 1" mesh="left_wrist_pitch_link"/>
                        <body name="left_wrist_yaw_link" pos="0.046 0 0">
                          <inertial pos="0.0708244 0.000191745 0.00161742" quat="0.510571 0.526295 0.468078 0.493188" mass="0.254576" diaginertia="0.000646113 0.000559993 0.000147566"/>
                          <joint name="left_wrist_yaw_joint" pos="0 0 0" axis="0 0 1" range="-1.61443 1.61443" actuatorfrcrange="-5 5"/>
                          <geom type="mesh" contype="0" conaffinity="0" group="1" density="0" rgba="0.7 0.7 0.7 1" mesh="left_wrist_yaw_link"/>
                          <geom type="mesh" rgba="0.7 0.7 0.7 1" mesh="left_wrist_yaw_link"/>
                          <geom name="left_rubber_hand_collision" pos="0.0415 0.003 0" quat="1 0 0 0" type="mesh" contype="1" conaffinity="1" group="1" density="0" rgba="0.7 0.7 0.7 1" mesh="left_rubber_hand" friction="8.0 0.8 0.08" condim="4"/>
                        </body>
                      </body>
                    </body>
                  </body>
                </body>
              </body>
            </body>
            <body name="right_shoulder_pitch_link" pos="0.0039563 -0.10021 0.24778" quat="0.990264 -0.139201 1.38722e-05 9.86868e-05">
              <inertial pos="0 -0.035892 -0.011628" quat="0.68225 -0.326267 0.0130458 0.654152" mass="0.718" diaginertia="0.000465864 0.000432842 0.000406394"/>
              <joint name="right_shoulder_pitch_joint" pos="0 0 0" axis="0 1 0" range="-3.0892 2.6704" actuatorfrcrange="-25 25"/>
              <geom type="mesh" contype="0" conaffinity="0" group="1" density="0" rgba="0.7 0.7 0.7 1" mesh="right_shoulder_pitch_link"/>
              <geom size="0.03 0.025" pos="0 -0.04 -0.01" quat="0.707107 0 0.707107 0" type="cylinder" rgba="0.7 0.7 0.7 1"/>
              <body name="right_shoulder_roll_link" pos="0 -0.038 -0.013831" quat="0.990268 0.139172 0 0">
                <inertial pos="-0.000227 -0.00727 -0.063243" quat="0.712604 -0.00710317 -0.0196223 0.701256" mass="0.643" diaginertia="0.000691311 0.000618011 0.000388977"/>
                <joint name="right_shoulder_roll_joint" pos="0 0 0" axis="1 0 0" range="-2.2515 1.5882" actuatorfrcrange="-25 25"/>
                <geom type="mesh" contype="0" conaffinity="0" group="1" density="0" rgba="0.7 0.7 0.7 1" mesh="right_shoulder_roll_link"/>
                <geom size="0.03 0.015" pos="-0.004 -0.006 -0.053" type="cylinder" rgba="0.7 0.7 0.7 1"/>
                <body name="right_shoulder_yaw_link" pos="0 -0.00624 -0.1032">
                  <inertial pos="0.010773 0.002949 -0.072009" quat="0.687134 -0.0679942 -0.0964829 0.716879" mass="0.734" diaginertia="0.00106187 0.00103217 0.000400661"/>
                  <joint name="right_shoulder_yaw_joint" pos="0 0 0" axis="0 0 1" range="-2.618 2.618" actuatorfrcrange="-25 25"/>
                  <geom type="mesh" contype="0" conaffinity="0" group="1" density="0" rgba="0.7 0.7 0.7 1" mesh="right_shoulder_yaw_link"/>
                  <geom type="mesh" rgba="0.7 0.7 0.7 1" mesh="right_shoulder_yaw_link"/>
                  <body name="right_elbow_link" pos="0.015783 0 -0.080518">
                    <inertial pos="0.064956 -0.004454 -0.010062" quat="0.388129 0.388821 0.636132 0.541765" mass="0.6" diaginertia="0.000443035 0.000421612 0.000259353"/>
                    <joint name="right_elbow_joint" pos="0 0 0" axis="0 1 0" range="-1.0472 2.0944" actuatorfrcrange="-25 25"/>
                    <geom type="mesh" contype="0" conaffinity="0" group="1" density="0" rgba="0.7 0.7 0.7 1" mesh="right_elbow_link"/>
                    <geom type="mesh" rgba="0.7 0.7 0.7 1" mesh="right_elbow_link"/>
                    <body name="right_wrist_roll_link" pos="0.1 -0.00188791 -0.01">
                      <inertial pos="0.0171394 -0.000537591 4.8864e-07" quat="0.411667 0.575338 -0.411094 0.574906" mass="0.085445" diaginertia="5.48211e-05 4.96646e-05 3.57798e-05"/>
                      <joint name="right_wrist_roll_joint" pos="0 0 0" axis="1 0 0" range="-1.97222 1.97222" actuatorfrcrange="-25 25"/>
                      <geom type="mesh" contype="0" conaffinity="0" group="1" density="0" rgba="0.7 0.7 0.7 1" mesh="right_wrist_roll_link"/>
                      <geom type="mesh" rgba="0.7 0.7 0.7 1" mesh="right_wrist_roll_link"/>
                      <body name="right_wrist_pitch_link" pos="0.038 0 0">
                        <inertial pos="0.0229999 0.00111685 -0.00111658" quat="0.643608 0.293036 0.661363 0.249998" mass="0.48405" diaginertia="0.000430353 0.000429873 0.000164648"/>
                        <joint name="right_wrist_pitch_joint" pos="0 0 0" axis="0 1 0" range="-1.61443 1.61443" actuatorfrcrange="-5 5"/>
                        <geom type="mesh" contype="0" conaffinity="0" group="1" density="0" rgba="0.7 0.7 0.7 1" mesh="right_wrist_pitch_link"/>
                        <geom type="mesh" rgba="0.7 0.7 0.7 1" mesh="right_wrist_pitch_link"/>
                        <body name="right_wrist_yaw_link" pos="0.046 0 0">
                          <inertial pos="0.0708244 -0.000191745 0.00161742" quat="0.493188 0.468078 0.526295 0.510571" mass="0.254576" diaginertia="0.000646113 0.000559993 0.000147566"/>
                          <joint name="right_wrist_yaw_joint" pos="0 0 0" axis="0 0 1" range="-1.61443 1.61443" actuatorfrcrange="-5 5"/>
                          <geom type="mesh" contype="0" conaffinity="0" group="1" density="0" rgba="0.7 0.7 0.7 1" mesh="right_wrist_yaw_link"/>
                          <geom type="mesh" rgba="0.7 0.7 0.7 1" mesh="right_wrist_yaw_link"/>
                          <geom name="right_rubber_hand_collision" pos="0.0415 -0.003 0" quat="1 0 0 0" type="mesh" contype="1" conaffinity="1" group="1" density="0" rgba="0.7 0.7 0.7 1" mesh="right_rubber_hand" friction="8.0 0.8 0.08" condim="4"/>
                        </body>
                      </body>
                    </body>
                  </body>
                </body>
              </body>
            </body>
          </body>
        </body>
      </body>
    </body>
  </worldbody>

  <actuator>
    <motor name="left_hip_pitch_joint" joint="left_hip_pitch_joint"/>
    <motor name="left_hip_roll_joint" joint="left_hip_roll_joint"/>
    <motor name="left_hip_yaw_joint" joint="left_hip_yaw_joint"/>
    <motor name="left_knee_joint" joint="left_knee_joint"/>
    <motor name="left_ankle_pitch_joint" joint="left_ankle_pitch_joint"/>
    <motor name="left_ankle_roll_joint" joint="left_ankle_roll_joint"/>
    <motor name="right_hip_pitch_joint" joint="right_hip_pitch_joint"/>
    <motor name="right_hip_roll_joint" joint="right_hip_roll_joint"/>
    <motor name="right_hip_yaw_joint" joint="right_hip_yaw_joint"/>
    <motor name="right_knee_joint" joint="right_knee_joint"/>
    <motor name="right_ankle_pitch_joint" joint="right_ankle_pitch_joint"/>
    <motor name="right_ankle_roll_joint" joint="right_ankle_roll_joint"/>
    <motor name="waist_yaw_joint" joint="waist_yaw_joint"/>
    <motor name="waist_roll_joint" joint="waist_roll_joint"/>
    <motor name="waist_pitch_joint" joint="waist_pitch_joint"/>
    <motor name="left_shoulder_pitch_joint" joint="left_shoulder_pitch_joint"/>
    <motor name="left_shoulder_roll_joint" joint="left_shoulder_roll_joint"/>
    <motor name="left_shoulder_yaw_joint" joint="left_shoulder_yaw_joint"/>
    <motor name="left_elbow_joint" joint="left_elbow_joint"/>
    <motor name="left_wrist_roll_joint" joint="left_wrist_roll_joint"/>
    <motor name="left_wrist_pitch_joint" joint="left_wrist_pitch_joint"/>
    <motor name="left_wrist_yaw_joint" joint="left_wrist_yaw_joint"/>
    <motor name="right_shoulder_pitch_joint" joint="right_shoulder_pitch_joint"/>
    <motor name="right_shoulder_roll_joint" joint="right_shoulder_roll_joint"/>
    <motor name="right_shoulder_yaw_joint" joint="right_shoulder_yaw_joint"/>
    <motor name="right_elbow_joint" joint="right_elbow_joint"/>
    <motor name="right_wrist_roll_joint" joint="right_wrist_roll_joint"/>
    <motor name="right_wrist_pitch_joint" joint="right_wrist_pitch_joint"/>
    <motor name="right_wrist_yaw_joint" joint="right_wrist_yaw_joint"/>
  </actuator>

  <sensor>
    <gyro name="imu-torso-angular-velocity" site="imu_in_torso" noise="5e-4" cutoff="34.9"/>
    <accelerometer name="imu-torso-linear-acceleration" site="imu_in_torso" noise="1e-2" cutoff="157"/>
    <gyro name="imu-pelvis-angular-velocity" site="imu_in_pelvis" noise="5e-4" cutoff="34.9"/>
    <accelerometer name="imu-pelvis-linear-acceleration" site="imu_in_pelvis" noise="1e-2" cutoff="157"/>
  </sensor>


  <!-- setup scene -->
  <statistic center="1.0 0.7 1.0" extent="0.8"/>
  <visual>
    <headlight diffuse="0.6 0.6 0.6" ambient="0.1 0.1 0.1" specular="0.9 0.9 0.9"/>
    <rgba haze="0.15 0.25 0.35 1"/>
    <global azimuth="-140" elevation="-20"/>
  </visual>
  <asset>
    <texture type="skybox" builtin="flat" rgb1="0 0 0" rgb2="0 0 0" width="512" height="3072"/>
    <texture type="2d" name="groundplane" builtin="checker" mark="edge" rgb1="0.2 0.3 0.4" rgb2="0.1 0.2 0.3" markrgb="0.8 0.8 0.8" width="300" height="300"/>
    <material name="groundplane" texture="groundplane" texuniform="true" texrepeat="5 5" reflectance="0.2"/>
    <!-- triangular prism (convex hull of 6 vertices); extruded along y -->
    <mesh name="tri_prism" vertex="-0.06 0.06 0  0.06 0.06 0  0 0.06 0.10  -0.06 -0.06 0  0.06 -0.06 0  0 -0.06 0.10"/>
  </asset>
  <worldbody>
    <light pos="1 0 3.5" dir="0 0 -1" directional="true"/>
    <geom name="floor" size="0 0 0.05" type="plane" material="groundplane" friction="1.5 0.02 0.002" condim="4"/>

    <!-- fixed monitor cameras for table-object-hand debugging -->
    <camera name="top_down" pos="1.05 0 1.75" xyaxes="1 0 0 0 1 0" fovy="55"/>
    <camera name="side_view" pos="1.05 -1.25 0.95" xyaxes="1 0 0 0 0.119 0.993" fovy="55"/>

    <!-- table: static collision object -->
    <body name="table" pos="1.2 0 0.65">
      <geom name="table_top"
            type="box"
            rgba="0.45 0.28 0.12 1"
            size="0.45 0.35 0.06"
            pos="0 0 0"
            friction="1.0 0.02 0.002"
            condim="4"/>
      <geom name="table_leg_fl"
            type="box"
            rgba="0.30 0.18 0.08 1"
            size="0.035 0.035 0.295"
            pos="0.35 0.25 -0.355"
            friction="1.0 0.02 0.002"
            condim="4"/>
      <geom name="table_leg_fr"
            type="box"
            rgba="0.30 0.18 0.08 1"
            size="0.035 0.035 0.295"
            pos="0.35 -0.25 -0.355"
            friction="1.0 0.02 0.002"
            condim="4"/>
      <geom name="table_leg_bl"
            type="box"
            rgba="0.30 0.18 0.08 1"
            size="0.035 0.035 0.295"
            pos="-0.35 0.25 -0.355"
            friction="1.0 0.02 0.002"
            condim="4"/>
      <geom name="table_leg_br"
            type="box"
            rgba="0.30 0.18 0.08 1"
            size="0.035 0.035 0.295"
            pos="-0.35 -0.25 -0.355"
            friction="1.0 0.02 0.002"
            condim="4"/>
    </body>

    <!-- table_back: static collision object behind the robot -->
    <body name="table_back" pos="-1.2 0 0.65">
      <geom name="table_back_top"
            type="box"
            rgba="0.45 0.28 0.12 1"
            size="0.45 0.35 0.06"
            pos="0 0 0"
            friction="1.0 0.02 0.002"
            condim="4"/>
      <geom name="table_back_leg_fl"
            type="box"
            rgba="0.30 0.18 0.08 1"
            size="0.035 0.035 0.295"
            pos="0.35 0.25 -0.355"
            friction="1.0 0.02 0.002"
            condim="4"/>
      <geom name="table_back_leg_fr"
            type="box"
            rgba="0.30 0.18 0.08 1"
            size="0.035 0.035 0.295"
            pos="0.35 -0.25 -0.355"
            friction="1.0 0.02 0.002"
            condim="4"/>
      <geom name="table_back_leg_bl"
            type="box"
            rgba="0.30 0.18 0.08 1"
            size="0.035 0.035 0.295"
            pos="-0.35 0.25 -0.355"
            friction="1.0 0.02 0.002"
            condim="4"/>
      <geom name="table_back_leg_br"
            type="box"
            rgba="0.30 0.18 0.08 1"
            size="0.035 0.035 0.295"
            pos="-0.35 -0.25 -0.355"
            friction="1.0 0.02 0.002"
            condim="4"/>
    </body>

    <!-- box: dynamic object on table -->
    <body name="box" pos="0.92 0 0.81">
      <freejoint/>
      <geom name="box_geom"
            type="box"
            size="0.10 0.10 0.10"
            mass="0.25"
            rgba="0.9 0.15 0.1 1"
            contype="1"
            conaffinity="1"
            friction="6.0 0.5 0.05"
            condim="4"/>
    </body>

    <!-- assorted dynamic objects on the front table (table top at z=0.71) -->
    <body name="ball" pos="1.10 0.20 0.77">
      <freejoint/>
      <geom name="ball_geom" type="sphere" size="0.06" mass="0.20" rgba="0.15 0.7 0.25 1"
            contype="1" conaffinity="1" friction="6.0 0.5 0.05" condim="4"/>
    </body>
    <body name="ellipsoid" pos="1.10 -0.20 0.76">
      <freejoint/>
      <geom name="ellipsoid_geom" type="ellipsoid" size="0.08 0.05 0.05" mass="0.20" rgba="0.7 0.25 0.8 1"
            contype="1" conaffinity="1" friction="6.0 0.5 0.05" condim="4"/>
    </body>
    <body name="cylinder" pos="1.45 -0.18 0.78">
      <freejoint/>
      <geom name="cylinder_geom" type="cylinder" size="0.05 0.07" mass="0.20" rgba="0.95 0.8 0.1 1"
            contype="1" conaffinity="1" friction="6.0 0.5 0.05" condim="4"/>
    </body>
    <body name="prism" pos="1.45 0.18 0.72">
      <freejoint/>
      <geom name="prism_geom" type="mesh" mesh="tri_prism" mass="0.20" rgba="0.2 0.55 0.9 1"
            contype="1" conaffinity="1" friction="6.0 0.5 0.05" condim="4"/>
    </body>

    <!-- ===================== furniture (static collision objects) ===================== -->

    <!-- bed: long axis along x, placed on the +y side of the room -->
    <body name="bed" pos="0 2.3 0">
      <geom name="bed_frame"   type="box" rgba="0.45 0.28 0.12 1" size="1.00 0.70 0.08" pos="0 0 0.32"  friction="1.0 0.02 0.002" condim="4"/>
      <geom name="bed_mattress" type="box" rgba="0.85 0.85 0.92 1" size="0.95 0.65 0.10" pos="0 0 0.50"  friction="1.0 0.02 0.002" condim="4"/>
      <geom name="bed_pillow"  type="box" rgba="0.95 0.95 0.98 1" size="0.28 0.50 0.06" pos="-0.60 0 0.62" friction="1.0 0.02 0.002" condim="4"/>
      <geom name="bed_headboard" type="box" rgba="0.35 0.22 0.10 1" size="0.05 0.70 0.30" pos="-0.99 0 0.70" friction="1.0 0.02 0.002" condim="4"/>
      <geom name="bed_leg_fl" type="box" rgba="0.30 0.18 0.08 1" size="0.05 0.05 0.12" pos="0.90 0.60 0.12"  friction="1.0 0.02 0.002" condim="4"/>
      <geom name="bed_leg_fr" type="box" rgba="0.30 0.18 0.08 1" size="0.05 0.05 0.12" pos="0.90 -0.60 0.12" friction="1.0 0.02 0.002" condim="4"/>
      <geom name="bed_leg_bl" type="box" rgba="0.30 0.18 0.08 1" size="0.05 0.05 0.12" pos="-0.90 0.60 0.12"  friction="1.0 0.02 0.002" condim="4"/>
      <geom name="bed_leg_br" type="box" rgba="0.30 0.18 0.08 1" size="0.05 0.05 0.12" pos="-0.90 -0.60 0.12" friction="1.0 0.02 0.002" condim="4"/>
    </body>

    <!-- nightstand: small cabinet beside the bed -->
    <body name="nightstand" pos="1.30 2.10 0">
      <geom name="nightstand_body" type="box" rgba="0.40 0.25 0.11 1" size="0.18 0.18 0.20" pos="0 0 0.20" friction="1.0 0.02 0.002" condim="4"/>
      <geom name="nightstand_top"  type="box" rgba="0.50 0.32 0.14 1" size="0.20 0.20 0.02" pos="0 0 0.42" friction="1.0 0.02 0.002" condim="4"/>
    </body>

    <!-- chair: on the -y side, seat + backrest + four legs -->
    <body name="chair" pos="0 -2.0 0">
      <geom name="chair_seat" type="box" rgba="0.55 0.35 0.18 1" size="0.22 0.22 0.03" pos="0 0 0.45" friction="1.0 0.02 0.002" condim="4"/>
      <geom name="chair_back" type="box" rgba="0.55 0.35 0.18 1" size="0.22 0.03 0.25" pos="0 -0.19 0.70" friction="1.0 0.02 0.002" condim="4"/>
      <geom name="chair_leg_fl" type="box" rgba="0.40 0.25 0.12 1" size="0.025 0.025 0.225" pos="0.18 0.18 0.225"  friction="1.0 0.02 0.002" condim="4"/>
      <geom name="chair_leg_fr" type="box" rgba="0.40 0.25 0.12 1" size="0.025 0.025 0.225" pos="0.18 -0.18 0.225" friction="1.0 0.02 0.002" condim="4"/>
      <geom name="chair_leg_bl" type="box" rgba="0.40 0.25 0.12 1" size="0.025 0.025 0.225" pos="-0.18 0.18 0.225"  friction="1.0 0.02 0.002" condim="4"/>
      <geom name="chair_leg_br" type="box" rgba="0.40 0.25 0.12 1" size="0.025 0.025 0.225" pos="-0.18 -0.18 0.225" friction="1.0 0.02 0.002" condim="4"/>
    </body>

    <!-- wardrobe: tall cabinet in the back-left corner -->
    <body name="wardrobe" pos="-2.0 1.6 0">
      <geom name="wardrobe_body" type="box" rgba="0.38 0.24 0.12 1" size="0.30 0.55 0.95" pos="0 0 0.95" friction="1.0 0.02 0.002" condim="4"/>
      <geom name="wardrobe_handle_l" type="box" rgba="0.85 0.85 0.20 1" size="0.02 0.02 0.10" pos="0.31 -0.12 1.05" friction="1.0 0.02 0.002" condim="4"/>
      <geom name="wardrobe_handle_r" type="box" rgba="0.85 0.85 0.20 1" size="0.02 0.02 0.10" pos="0.31 0.12 1.05"  friction="1.0 0.02 0.002" condim="4"/>
    </body>

    <!-- bookshelf: side wall + three shelf planks in the front-right corner -->
    <body name="bookshelf" pos="2.4 -1.8 0">
      <geom name="bookshelf_side_l" type="box" rgba="0.42 0.27 0.13 1" size="0.18 0.03 0.70" pos="0 -0.47 0.70" friction="1.0 0.02 0.002" condim="4"/>
      <geom name="bookshelf_side_r" type="box" rgba="0.42 0.27 0.13 1" size="0.18 0.03 0.70" pos="0 0.47 0.70"  friction="1.0 0.02 0.002" condim="4"/>
      <geom name="bookshelf_shelf_0" type="box" rgba="0.50 0.32 0.15 1" size="0.18 0.50 0.02" pos="0 0 0.04" friction="1.0 0.02 0.002" condim="4"/>
      <geom name="bookshelf_shelf_1" type="box" rgba="0.50 0.32 0.15 1" size="0.18 0.50 0.02" pos="0 0 0.50" friction="1.0 0.02 0.002" condim="4"/>
      <geom name="bookshelf_shelf_2" type="box" rgba="0.50 0.32 0.15 1" size="0.18 0.50 0.02" pos="0 0 0.96" friction="1.0 0.02 0.002" condim="4"/>
      <geom name="bookshelf_back" type="box" rgba="0.35 0.22 0.10 1" size="0.02 0.50 0.70" pos="-0.18 0 0.70" friction="1.0 0.02 0.002" condim="4"/>
    </body>

    <body name="viz_root_target" mocap="true" pos="0 0 -10">
      <geom type="sphere" size="0.04" rgba="1 0.35 0.2 0.9" contype="0" conaffinity="0"/>
    </body>
    <body name="viz_left_ee_target" mocap="true" pos="0 0 -10">
      <geom type="sphere" size="0.035" rgba="0.2 0.7 1 0.95" contype="0" conaffinity="0"/>
    </body>
    <body name="viz_right_ee_target" mocap="true" pos="0 0 -10">
      <geom type="sphere" size="0.035" rgba="0.2 1 0.4 0.95" contype="0" conaffinity="0"/>
    </body>
    <body name="viz_root_dir" mocap="true" pos="0 0 -10" quat="1 0 0 0">
      <geom name="viz_root_dir_shaft" type="box" pos="0.15 0 0" size="0.15 0.012 0.012" rgba="1 0.75 0.1 0.75" contype="0" conaffinity="0"/>
      <geom name="viz_root_dir_tip" type="sphere" pos="0.3 0 0" size="0.024" rgba="1 0.85 0.2 0.95" contype="0" conaffinity="0"/>
    </body>

    <!-- coordinate-frame axes (X=red, Y=green, Z=blue) for teleop targets -->
    <body name="viz_root_frame" mocap="true" pos="0 0 -10" quat="1 0 0 0">
      <geom name="viz_root_frame_x" type="cylinder" fromto="0 0 0 0.18 0 0" size="0.012" rgba="1 0 0 1" contype="0" conaffinity="0"/>
      <geom name="viz_root_frame_y" type="cylinder" fromto="0 0 0 0 0.18 0" size="0.012" rgba="0 1 0 1" contype="0" conaffinity="0"/>
      <geom name="viz_root_frame_z" type="cylinder" fromto="0 0 0 0 0 0.18" size="0.012" rgba="0 0 1 1" contype="0" conaffinity="0"/>
    </body>
    <body name="viz_left_ee_frame" mocap="true" pos="0 0 -10" quat="1 0 0 0">
      <geom name="viz_left_ee_frame_x" type="cylinder" fromto="0 0 0 0.12 0 0" size="0.008" rgba="1 0 0 1" contype="0" conaffinity="0"/>
      <geom name="viz_left_ee_frame_y" type="cylinder" fromto="0 0 0 0 0.12 0" size="0.008" rgba="0 1 0 1" contype="0" conaffinity="0"/>
      <geom name="viz_left_ee_frame_z" type="cylinder" fromto="0 0 0 0 0 0.12" size="0.008" rgba="0 0 1 1" contype="0" conaffinity="0"/>
    </body>
    <body name="viz_right_ee_frame" mocap="true" pos="0 0 -10" quat="1 0 0 0">
      <geom name="viz_right_ee_frame_x" type="cylinder" fromto="0 0 0 0.12 0 0" size="0.008" rgba="1 0 0 1" contype="0" conaffinity="0"/>
      <geom name="viz_right_ee_frame_y" type="cylinder" fromto="0 0 0 0 0.12 0" size="0.008" rgba="0 1 0 1" contype="0" conaffinity="0"/>
      <geom name="viz_right_ee_frame_z" type="cylinder" fromto="0 0 0 0 0 0.12" size="0.008" rgba="0 0 1 1" contype="0" conaffinity="0"/>
    </body>
  </worldbody>
</mujoco>
